Workbook

Sheet Table of Contents
A1: TITAN COMPANY LIMITED - EQUITY VALUATION REPORT
A2: Discounted Cash Flow & Relative Valuation | Base Case | FY2026–FY2030 Forecast
A3: Sr. | B3: Section | C3: Sheet Name | D3: Description | E3: Type
A4: 1 | B4: Background | C4: SOURCES | D4: Data sources and bases of all assumptions used | E4: Supporting
A5: 2 | B5: Background | C5: ABOUT THE COMPANY | D5: Company overview, business segments, key financials | E5: Supporting
A6: 3 | B6: Macro Analysis | C6: ECONOMY ANALYSIS | D6: GDP growth, CPI inflation, USD/INR - macro context for Titan | E6: Analysis
A7: 4 | B7: Sector Analysis | C7: INDUSTRY ANALYSIS | D7: Gold demand, jewellery sector data and market dynamics | E7: Analysis
A8: 5 | B8: Model Input | C8: BETA | D8: Historical beta using SENSEX & Titan price data (2011–2025) | E8: Input
A9: 6 | B9: Model Input | C9: WACC & EVA | D9: WACC = 10.51% | Ke = 13.38% | Kd = 9.27% | EVA computed | E9: Input
A10: 7 | B10: Valuation | C10: DDM | D10: Dividend Discount Model - Gordon Growth, Rs. 273.6/share | E10: Valuation
A11: 8 | B11: Model Input | C11: Assumptions | D11: All P&L, Balance Sheet, PPE assumptions - 3 scenarios | E11: Input
A12: 9 | B12: Financial Model | C12: FS | D12: Forecasted P&L and Balance Sheet - FY2019A to FY2030F | E12: Model
A13: 10 | B13: Financial Model | C13: CFS | D13: Indirect Cash Flow Statement - FY2019A to FY2030F | E13: Model
A14: 11 | B14: Analysis | C14: OPERATING CYCLE | D14: Inventory, Debtor, Creditor days - Gross & Net cycle | E14: Analysis
A15: 12 | B15: Valuation | C15: DCF Valuation | D15: 2-Stage FCFF DCF | Intrinsic Value Rs. 181/share | Sensitivity | E15: Valuation
... A18: 15 | B18: Summary | C18: Key Ratio Forecast | D18: Key ratios dashboard with trend chart | E18: Summary
A20: VALUATION SUMMARY AT A GLANCE
B21: Company | C21: Titan Company Limited - NSE / BSE Listed
B22: Sector | C22: Consumer Discretionary - Organised Jewellery & Accessories
B23: Valuation Base | C23: FY2025 Actuals | 5-Year Explicit Forecast FY2026–FY2030
B24: WACC | C24: 10.51% | Terminal Growth Rate: 5.0%
B25: DCF Fair Value | C25: Rs. 181 per share (2-Stage FCFF)
B26: DDM Value | C26: Rs. 274 per share (Gordon Growth Model)
B27: CMP (Approx.) | C27: Rs. 3,300 per share
B28: Nature | C28: Premium growth stock - CMP prices in long-term growth optionality

Sheet SOURCES
A1: S. no. | B1: Details of assumptions | C1: Assumed Figure | D1: Remarks | E1: URL
A2: 1 | B2: Actual Financial Statement data for last 5 years | C2: - | D2: Financial statements has been taken for the last five years from capitaline database | E2: https://awsone.capitaline.com/index.html#/Company/Condensed/condensed?
A3: 2 | B3: GDP Growth | C3: - | D3: GDP Growth percent has been taken for the last 10 years | E3: https://data.worldbank.org/indicator/NY.GDP.MKTP.KD.ZG?locations=IN
A4: 3 | B4: CPI Inflation | C4: - | D4: CPI Inflation has been taken for the last 10 years | E4: https://tradingeconomics.com/india/inflation-cpi
A5: 4 | B5: Gold Prices | C5: - | D5: Gold Prices has been taken for the last 10 years | E5: https://www.gold.org/goldhub/data/gold-prices
A6: 5 | B6: Repo Rate | C6: - | D6: Repo Rate percent has been taken for the last 10 years | E6: https://rbi.org.in/Scripts/AnnualPublications.aspx?head=Handbook%20of%20Statistics%20on%20Indian%20Economy
A7: 6 | B7: Gold Demand | C7: - | D7: Gold Demand has been taken for the last 10 years | E7: https://www.gold.org/goldhub/data/gold-prices
A8: 7 | B8: Jewellery Demand | C8: - | D8: Jewellery demand has been taken for the last 10 years | E8: https://www.gjepc.org
A9: 8 | B9: Organised Share | C9: - | D9: Organised Sector Share has been taken for the last 10 years | E9: https://www.ibef.org
A10: 9 | B10: Sensex rates | C10: - | D10: Data frame : 2011-2025 | E10: https://www.bseindia.com/markets/equity/EQReports/StockPrcHistori.aspx?expandable=7&scripcode=500114&flag=sp&Submit=G
A11: 10 | B11: Titan Rates | C11: - | D11: Data frame : 2011-2025 | E11: https://www.bseindia.com/markets/equity/EQReports/StockPrcHistori.aspx?expandable=7&scripcode=500114&flag=sp&Submit=G
A12: 11 | B12: Risk Free Rate | C12: 0.0668 | D12: Shows India 10-year G-Sec yield (current and historical) | E12: https://tradingeconomics.com/india/government-bond-yield
A13: 12 | B13: Tax | C13: 0.2517
A14: 13 | B14: Revenue Growth | C14: 0.0887 | D14: India's Gems & Jewellery market is projected to grow from US$ 85 billion (2025) to US$ 130 billion by 2030, implying a CAGR of approximately 8.87% per year | E14: https://www.ibef.org/industry/gems-jewellery-india
A15: 14 | B15: Peer Company Multiples | C15: - | D15: Multiples are approximations as of March 2025 and used for relative valuation comparison only. | E15: screener.in , bseindia.com
A16: 15 | B16: Current Market price | C16: Rs. 3300 (approx) | D16: NSE/BSE market data - approximate price used for valuation comparison purposes only.
A17: 16 | B17: Market return | C17: 0.15 | D17: Annualised Return value

Sheet ABOUT THE COMPANY
B2: ABOUT THE COMPANY | E2: Business Segments of Titan Company Ltd
B3: Company Name | C3: Titan Company Ltd | E3: Segment | F3: Key Brands / Activities | G3: Business Description
B4: Listing | C4: NSE / BSE | E4: Jewellery Division | F4: Tanishq, Mia, Zoya, CaratLane | G4: Largest revenue and profit contributor. Engaged in design, manufacture, and retail of gold, studded, and premium jewellery through a pan-India retail network and digital channels.
B5: Sector | C5: Consumer Discretionary | E5: Watches & Wearables Division | F5: Titan, Fastrack, Sonata, Smart Wearables | G5: Includes analog watches, smart wearables, and accessories. Positioned as a lifestyle and fashion category driven by innovation and brand strength.
B6: Industry | C6: Jewellery & Lifestyle Retail | E6: Eyewear Division | F6: Titan Eye+ | G6: Organized eyewear retail business offering prescription glasses, sunglasses, lenses, and optical services through exclusive retail stores.
B7: Founded | C7: 1984 | E7: Emerging Businesses / Others | F7: Taneira (Ethnic Wear), Fragrances, Fashion Accessories | G7: Comprises new growth verticals aimed at diversifying Titan’s lifestyle portfolio. Currently smaller in scale but strategically important for long-term growth.
B8: Headquarters | C8: Bengaluru, India
B9: Promoter / Parent | C9: Tata Group | E9: Growth Drivers – Titan Company Ltd
B10: Market Cap | C10: Rs. 3.8 Trillion | E10: Growth Driver | F10: Explanation | G10: Valuation Significance
E11: Expansion of Organized Jewellery Market | F11: Increasing consumer preference for trusted and transparent brands over unorganized players. Regulatory formalization accelerates market share shift. | G11: Supports long-term revenue growth assumptions and market share gains.
B12: Titan Company Ltd represents a structurally strong play on India’s organized jewellery market growth. Strong brand equity, store expansion, and premiumization trends support long-term earnings visibility. However, profitability remains sensitive to gold price cycles and discretionary demand shifts. | E12: Retail Store Network Expansion | F12: Continuous addition of stores enhances geographic reach, customer acquisition, and sales scalability. | G12: Drives structural growth and operating leverage.
E13: Rising Studded Jewellery Mix | F13: Higher contribution from studded and premium jewellery categories. | G13: Margin-accretive growth; improves profitability forecasts.
E14: Premiumization & Lifestyle Positioning | F14: Consumers shifting toward branded, design-led, and premium products. | G14: Supports pricing power and margin stability.
E15: Digital / Omni-Channel Growth | F15: Growth via CaratLane and online channels targeting younger demographics. | G15: Expands addressable market and improves sales efficiency.
E16: Wedding & Festive Demand Resilience | F16: Jewellery demand driven by cultural and demographic factors. | G16: Provides demand stability and cyclicality buffer.
E17: Category Diversification | F17: Growth in eyewear, wearables, ethnic wear (Taneira), and accessories. | G17: Reduces business concentration risk and adds optionality.
E18: Brand Strength & Customer Loyalty | F18: Strong recall and trust create repeat purchases and cross-selling opportunities. | G18: Enhances revenue visibility and competitive durability.
B20: Economic Moat - Titan Company Ltd
B21: Titan Company Ltd possesses a strong economic moat driven primarily by brand trust, retail scale, and leadership in India’s organized jewellery market. The company’s flagship brand Tanishq enjoys significant consumer confidence, a decisive advantage in a category where authenticity and transparency influence purchase decisions. Titan’s extensive retail network creates meaningful entry barriers while enabling operating leverage. Pricing power derived from brand equity supports margin resilience despite gold price volatility. Additionally, Tata Group backing strengthens governance credibility and strategic positioning. Investments in digital channels and omni-channel integration further reinforce Titan’s competitive advantages and long-term growth potential.

Sheet ECONOMY ANALYSIS
A1: Year | B1: Real GDP Growth (%) | C1: CPI Inflation (%) | D1: USD/INR (Avg) | E1: Gold Price (Rs. / 10g Avg) | F1: Repo Rate (%)
A2: 2015 | B2: 8 | C2: 4.9 | D2: 64.1 | E2: 26343 | F2: 7.5
A3: 2016 | B3: 8.3 | C3: 4.9 | D3: 67.2 | E3: 28623 | F3: 6.5
A4: 2017 | B4: 6.8 | C4: 3.3 | D4: 65.1 | E4: 29667 | F4: 6.25
A5: 2018 | B5: 6.5 | C5: 3.9 | D5: 68.4 | E5: 31438 | F5: 6.25
A6: 2019 | B6: 4 | C6: 4.8 | D6: 70.4 | E6: 35220 | F6: 5.15
A7: 2020 | B7: -5.8 | C7: 6.6 | D7: 74.1 | E7: 48651 | F7: 4
A8: 2021 | B8: 9.1 | C8: 5.1 | D8: 73.9 | E8: 48720 | F8: 4
A9: 2022 | B9: 7 | C9: 6.7 | D9: 78.6 | E9: 52670 | F9: 6.25
A10: 2023 | B10: 7.6 | C10: 5.6 | D10: 82.2 | E10: 65330 | F10: 6.5
A11: 2024 | B11: 6.5 | C11: 5 | D11: 83.1 | E11: 64070 | F11: 6.5
A12: 2025 | B12: 6.5 | C12: 4.8 | D12: 83 | E12: 72000 | F12: 5.25
A14: Year | B14: Gold Price Growth | C14: GDP Growth | D14: Real Income Proxy | E14: USD/INR Change
A15: 2015 | B15: 0 | C15: 0 | D15: =B2-C2 -> 3.1 | E15: 0
A16: 2016 | B16: =(E3/E2)-1 -> 0.086550507 | C16: =B3-B2 -> 0.3 | D16: =B3-C3 -> 3.4 | E16: =(D3/D2)-1 -> 0.048361934
A17: 2017 | B17: =(E4/E3)-1 -> 0.036474164 | C17: =B4-B3 -> -1.5 | D17: =B4-C4 -> 3.5 | E17: =(D4/D3)-1 -> -0.03125
A18: 2018 | B18: =(E5/E4)-1 -> 0.059695958 | C18: =B5-B4 -> -0.3 | D18: =B5-C5 -> 2.6 | E18: =(D5/D4)-1 -> 0.050691244 | I18: The gold price series indicates a significant long-term increase over the study period. Average prices rose from approximately Rs. 26,000 per 10 grams in the mid-2010s to levels exceeding Rs. 60,000–Rs. 70,000 in recent years. This represents a substantial rise in the underlying pricing base of jewellery products. Higher gold prices mechanically increase the value of jewellery transactions, thereby supporting industry revenue realization. However, elevated price levels may influence purchase volumes and product preferences, particularly in price-sensitive segments. The data suggests that gold price levels primarily affect ticket sizes, while volume sensitivity varies across demand cycles. | Q18: Year-on-year gold price growth shows noticeable variability, with certain years experiencing sharp increases. Periods of high growth reflect heightened price volatility rather than steady appreciation. Such phases may temporarily alter consumer purchase timing due to changing affordability conditions. From an industry perspective, higher growth rates may coincide with short-term demand adjustments, while stable growth periods are typically associated with more predictable purchasing patterns. The data highlights that volatility, rather than price direction alone, can affect demand behaviour.
A19: 2019 | B19: =(E6/E5)-1 -> 0.12030027 | C19: =B6-B5 -> -2.5 | D19: =B6-C6 -> -0.8 | E19: =(D6/D5)-1 -> 0.029239766
A20: 2020 | B20: =(E7/E6)-1 -> 0.38134583 | C20: =B7-B6 -> -9.8 | D20: =B7-C7 -> -12.4 | E20: =(D7/D6)-1 -> 0.052556818
A21: 2021 | B21: =(E8/E7)-1 -> 0.0014182648 | C21: =B8-B7 -> 14.9 | D21: =B8-C8 -> 4 | E21: =(D8/D7)-1 -> -0.0026990553
A22: 2022 | B22: =(E9/E8)-1 -> 0.081075534 | C22: =B9-B8 -> -2.1 | D22: =B9-C9 -> 0.3 | E22: =(D9/D8)-1 -> 0.063599459
A23: 2023 | B23: =(E10/E9)-1 -> 0.24036453 | C23: =B10-B9 -> 0.6 | D23: =B10-C10 -> 2 | E23: =(D10/D9)-1 -> 0.045801527
A24: 2024 | B24: =(E11/E10)-1 -> -0.019286698 | C24: =B11-B10 -> -1.1 | D24: =B11-C11 -> 1.5 | E24: =(D11/D10)-1 -> 0.010948905
A25: 2025 | B25: =(E12/E11)-1 -> 0.12377088 | C25: =B12-B11 -> 0 | D25: =B12-C12 -> 1.7 | E25: =(D12/D11)-1 -> -0.0012033694
A28: Across the study period, gold price levels and gold price growth exhibit the most pronounced movement among macro variables, directly influencing jewellery pricing and transaction values. GDP growth and real income indicators primarily affect demand momentum and affordability conditions. Exchange rate and interest rate movements further interact with gold pricing and consumption patterns. Collectively, the data suggests that jewellery industry performance is strongly linked to gold price dynamics and consumer income conditions.
I45: GDP growth data reflects fluctuations in economic expansion, including periods of moderation and recovery. Growth rates remained strong in several years, temporarily weakened during economic disruptions, and subsequently normalized. Jewellery demand, being income-sensitive, generally aligns with broader economic conditions. Higher GDP growth supports discretionary consumption capacity, whereas slower growth phases may moderate demand expansion. The data indicates that economic growth primarily influences industry demand momentum rather than pricing dynamics. | Q45: The Real Income Proxy captures changes in purchasing power by adjusting growth for inflation. Periods where GDP growth exceeded inflation indicate relatively stronger consumer affordability conditions. Conversely, narrowing spreads suggest pressure on real income. Jewellery purchases, which involve significant expenditure commitments, are sensitive to these affordability shifts. The data implies that real income conditions play a meaningful role in determining demand strength, particularly in discretionary and premium categories.

Sheet INDUSTRY ANALYSIS
A1: Year | B1: Total Gold Demand (Tonnes) | C1: Jewellery Demand (Tonnes) | D1: Investment Demand (Tonnes) | E1: Gold Imports (Tonnes) | F1: Avg Gold Price Trend | G1: Organized Share (%)
A2: 2015 | B2: 848 | C2: 612 | D2: 236 | E2: 900 | F2: Stable | G2: 0.3
A3: 2016 | B3: 666 | C3: 458 | D3: 208 | E3: 780 | F3: Rising | G3: 0.32
A4: 2017 | B4: 727 | C4: 562 | D4: 165 | E4: 880 | F4: Stable | G4: 0.34
A5: 2018 | B5: 760 | C5: 598 | D5: 162 | E5: 950 | F5: Rising | G5: 0.36
A6: 2019 | B6: 690 | C6: 544 | D6: 146 | E6: 840 | F6: Rising | G6: 0.38
A7: 2020 | B7: 446 | C7: 315 | D7: 131 | E7: 580 | F7: Sharp Rise | G7: 0.4
A8: 2021 | B8: 797 | C8: 611 | D8: 186 | E8: 1050 | F8: Moderation | G8: 0.42
A9: 2022 | B9: 774 | C9: 600 | D9: 174 | E9: 990 | F9: Rising | G9: 0.44
A10: 2023 | B10: 747 | C10: 575 | D10: 172 | E10: 920 | F10: Rising | G10: 0.46
A11: 2024 | B11: 780 | C11: 600 | D11: 180 | E11: 950 | F11: Elevated | G11: 0.48
A12: 2025 | B12: 800 | C12: 620 | D12: 180 | E12: 970 | F12: Elevated | G12: 0.5
A17: Across the study period, jewellery demand displays cyclical variability with repeated normalization following contraction phases. Demand levels post-recovery broadly align with historical ranges, indicating resilience in underlying consumption patterns. Total gold demand remains predominantly driven by jewellery consumption, while investment demand contributes greater volatility. Gold import data confirms persistent external supply dependence, with import volumes adjusting proportionally to domestic demand cycles. Simultaneously, organized market share shows steady expansion from roughly one-third of the market to nearly one-half, highlighting structural formalization within the industry. Collectively, the data suggests that short-term fluctuations are primarily cyclical, while long-term industry characteristics - consumption resilience and organized sector penetration - remain stable and supportive.
I18: The jewellery demand series shows clear cyclical movement rather than a persistent directional decline. Demand measured approximately 612 tonnes in 2015, moderated to around 458 tonnes in 2016, and subsequently recovered above 560–600 tonnes in later years. A sharp contraction is visible in 2020 (315 tonnes), followed by a strong normalization in 2021 (611 tonnes). Post-recovery demand levels remain broadly within historical ranges. The observed behaviour indicates temporary demand disruptions with subsequent normalization. Demand volatility appears event-driven rather than structurally weakening. | R18: Total gold demand consistently exceeds investment demand across all periods. For example, in 2015 total demand (~848 tonnes) materially exceeded investment demand (~236 tonnes). Even during contraction phases, jewellery demand remains the dominant component. Investment demand shows greater variability, declining sharply during certain periods while rebounding during uncertainty phases. Jewellery consumption represents the structural base of gold demand, while investment demand behaves more cyclically and sentiment-sensitive.
I45: Gold import volumes broadly track domestic demand patterns. Imports declined during disruption periods, notably in 2020 (~580 tonnes), compared with higher levels in preceding years. Subsequent recovery phases saw imports revert toward historical ranges, reflecting restoration of domestic consumption. No structural reduction in import reliance is observable. Industry supply dynamics remain externally dependent, with imports adjusting to consumption cycles rather than indicating permanent shifts. | R45: Organized market share exhibits a gradual but persistent expansion across the observation period. The share increased from approximately 30% in 2015 to levels approaching 48–50% by 2024–2025. The progression is visible across varying demand and price environments, with no meaningful reversals. Industry structure reflects a sustained reallocation toward organized retail channels, suggesting structural rather than cyclical change.

Sheet BETA
A1: HISTORICL BETA | H1: FUNDAMENTAL BETA
A2: Date | B2: SENSEX | C2: TITAN COMPANY | D2: MARKET RETURN | E2: FIRM RETURN | F2: SLOPE | H2: INPUT | I2: VALUE | K2: S.No. | L2: Debt to Cap | M2: D/E | N2: Levered Beta
A3: 40546 | B3: 20561.05 | C3: 3682.4 | H3: DEBT | I3: 28553 | K3: 1 | L3: 0 | M3: 0 | N3: =$I$8*(1+(M3)*(1-$I$5)) -> 0.30254073
A4: 40547 | B4: 20498.72 | C4: 3657.9 | D4: =LN(B4/B3) -> -0.0030360642 | E4: =LN(C4/C3) -> -0.0066755013 | F4: =SLOPE(E4:E3720,D4:D3720) -> 0.80743401 | H4: EQUITY | I4: 12803 | K4: 2 | L4: 0.1 | M4: =10%/90% -> 0.11111111 | N4: =$I$8*(1+(M4)*(1-$I$5)) -> 0.32769531
A5: 40548 | B5: 20301.1 | C5: 3640.25 | D5: =LN(B5/B4) -> -0.0096873734 | E5: =LN(C5/C4) -> -0.0048368516 | H5: TAX RATE | I5: 0.2517 | K5: 3 | L5: 0.25 | M5: =25/75 -> 0.33333333 | N5: =$I$8*(1+(M5)*(1-$I$5)) -> 0.37800447
A6: 40549 | B6: 20184.74 | C6: 3574 | D6: =LN(B6/B5) -> -0.0057481984 | E6: =LN(C6/C5) -> -0.018366944 | H6: Bl | I6: =F4 -> 0.80743401 | K6: 4 | L6: 0.35 | M6: =35/65 -> 0.53846154 | N6: =$I$8*(1+(M6)*(1-$I$5)) -> 0.4244437
A7: 40550 | B7: 19691.81 | C7: 3415.15 | D7: =LN(B7/B6) -> -0.02472406 | E7: =LN(C7/C6) -> -0.045464001 | H7: D/E | I7: =I3/I4 -> 2.2301804 | K7: 5 | L7: 0.5 | M7: =50/50 -> 1 | N7: =$I$8*(1+(M7)*(1-$I$5)) -> 0.52893196
A8: 40553 | B8: 19224.12 | C8: 3291.05 | D8: =LN(B8/B7) -> -0.024037073 | E8: =LN(C8/C7) -> -0.037014753 | H8: Bul | I8: =I6/(1+(I7)*(1-I5)) -> 0.30254073 | K8: 6 | L8: 0.75 | M8: =75/25 -> 3 | N8: =$I$8*(1+(M8)*(1-$I$5)) -> 0.98171441
A9: 40554 | B9: 19196.34 | C9: 3305.25 | D9: =LN(B9/B8) -> -0.0014461047 | E9: =LN(C9/C8) -> 0.0043054506
A10: 40555 | B10: 19534.1 | C10: 3568.3 | D10: =LN(B10/B9) -> 0.01744202 | E10: =LN(C10/C9) -> 0.076577178
A11: 40556 | B11: 19182.82 | C11: 3415.8 | D11: =LN(B11/B10) -> -0.018146569 | E11: =LN(C11/C10) -> -0.043677566
A12: 40557 | B12: 18860.44 | C12: 3410.55 | D12: =LN(B12/B11) -> -0.01694848 | E12: =LN(C12/C11) -> -0.0015381576
A13: 40560 | B13: 18882.25 | C13: 3429.6 | D13: =LN(B13/B12) -> 0.0011557206 | E13: =LN(C13/C12) -> 0.0055700677
A14: 40561 | B14: 19092.05 | C14: 3481.9 | D14: =LN(B14/B13) -> 0.011049691 | E14: =LN(C14/C13) -> 0.015134486
A15: 40562 | B15: 18978.32 | C15: 3459.1 | D15: =LN(B15/B14) -> -0.005974743 | E15: =LN(C15/C14) -> -0.0065696822
A16: 40563 | B16: 19046.54 | C16: 3479.45 | D16: =LN(B16/B15) -> 0.0035881827 | E16: =LN(C16/C15) -> 0.0058657957
A17: 40564 | B17: 19007.53 | C17: 3502.1 | D17: =LN(B17/B16) -> -0.0020502413 | E17: =LN(C17/C16) -> 0.0064885532
A18: 40567 | B18: 19151.28 | C18: 3576.35 | D18: =LN(B18/B17) -> 0.0075343377 | E18: =LN(C18/C17) -> 0.020979939
A19: 40568 | B19: 18969.45 | C19: 3593.95 | D19: =LN(B19/B18) -> -0.0095397637 | E19: =LN(C19/C18) -> 0.0049091489
A20: 40570 | B20: 18684.43 | C20: 3562.1 | D20: =LN(B20/B19) -> -0.015139234 | E20: =LN(C20/C19) -> -0.0089016176
... A3720: 46022 | B3720: 85220.6 | C3720: 4050.65 | D3720: =LN(B3720/B3719) -> 0.0064218452 | E3720: =LN(C3720/C3719) -> 0.019091636

Sheet WACC & EVA
A1: WACC
A2: INPUT | C2: VALUE
A3: Risk Free Premium | B3: Rf | C3: 0.0668
A4: Beta | B4: B | C4: =BETA!F4 -> 0.80743401
A5: Market Return | B5: MR | C5: =((1+F5)^365)-1 -> 0.14980786 | E5: Average Market Return | F5: =AVERAGE(BETA!D4:D3720) -> 0.0003825248
A6: Cost of Equity | B6: Ke | C6: =C3+C4*(C5-C3) -> 0.13382337
A7: Interest Expense | C7: 953
A8: Total Debt | C8: 10286
A9: Cost of Debt | B9: Kd | C9: =C7/C8 -> 0.092650204
A10: Tax Rate | B10: t | C10: 0.2517
A11: Total Equity | C11: 12803
A12: Weight of Equity | C12: =C11/(C11+C8) -> 0.55450647
A13: Weight of Debt | C13: =C8/(C8+C11) -> 0.44549353
A14: WACC | C14: =C12*C6+C13*C9*(1-C10) -> 0.10509206
A16: EVA
A17: INPUT | C17: VALUE
A18: WACC | C18: =C14 -> 0.10509206
A19: TOTAL CAPITAL EMPLOYED | C19: =C8+C11 -> 23089
A20: EBIT | C20: 5415
A21: TAX | C21: =C10 -> 0.2517
A22: NOPAT | C22: =C20*(1-C21) -> 4052.0445
A23: EVA | C23: =C22-(C18*C19) -> 1625.574

Sheet DDM
A1: YEAR | B1: 2015 | C1: 2016 | D1: 2017 | E1: 2018 | F1: 2019 | G1: 2020 | H1: 2021 | I1: 2022 | J1: 2023 | K1: 2024 | L1: 2025
A2: DPS | B2: 2.3 | C2: 2.2 | D2: 2.6 | E2: 3.75 | F2: 5 | G2: 4 | H2: 4 | I2: 7.5 | J2: 10 | K2: 11 | L2: 11
A3: DIVIDEND GROWTH | C3: =(C2/B2)-1 -> -0.043478261 | D3: =(D2/C2)-1 -> 0.18181818 | E3: =(E2/D2)-1 -> 0.44230769 | F3: =(F2/E2)-1 -> 0.33333333 | G3: =(G2/F2)-1 -> -0.2 | H3: =(H2/G2)-1 -> 0 | I3: =(I2/H2)-1 -> 0.875 | J3: =(J2/I2)-1 -> 0.33333333 | ... L3: =(L2/K2)-1 -> 0
A4: AVERAGE GROWTH | B4: =AVERAGE(C3:L3) -> 0.20223143 | C4: 0.09
A5: Ke | B5: ='WACC & EVA'!C6 -> 0.13382337
A6: Next Year Dividend | B6: =L2*(1+$C$4) -> 11.99
A7: Value Per Share | B7: =B6/(B5-C4) -> 273.59829
A9: Historical dividend growth exhibits significant variability, reflecting earnings cycles and payout policy adjustments. The raw average growth rate is not representative of long-term sustainable growth required for DDM. Accordingly, a normalized perpetual growth assumption of 9% is applied, consistent with mature consumer sector dynamics. Based on a cost of equity of 12.25%, the implied intrinsic value under the stable growth DDM framework is approximately ₹369 per share.

Sheet Assumptions
A1: ASSUMPTIONS: TITAN COMPANY LIMITED
I2: Scenarios: | K2: Y-o-Y Growth
A3: Selected Case | B3: Case 3 | I3: Case 1 | J3: Optimistic case | K3: =K4+0.02 -> 0.1087
I4: Case 2 | J4: Base case | K4: 0.0887
I5: Case 3 | J5: Worst case | K5: =K4-0.02 -> 0.0687
A6: P&L ASSUMPTIONS
A7: Particulars | B7: 2019 Actual | C7: 2020 Actual | D7: 2021 Actual | E7: 2022 Actual | F7: 2023 Actual | G7: 2024 Actual | H7: 2025 Actual | I7: 2026 Forecast | J7: 2027 Forecast | K7: 2028 Forecast | L7: 2029 Forecast | M7: 2030 Forecast
A8: Revenue from Operations | B8: =FS!B6 -> 19069.97 | C8: =FS!C6 -> 20010 | D8: =FS!D6 -> 20602 | E8: =FS!E6 -> 27210 | F8: =FS!F6 -> 38270 | G8: =FS!G6 -> 47114 | H8: =FS!H6 -> 54842 | I8: =H8*(1+I9) -> 58609.645 | J8: =I8*(1+J9) -> 62636.128 | K8: =J8*(1+K9) -> 66939.23 | L8: =K8*(1+L9) -> 71537.955 | M8: =L8*(1+M9) -> 76452.613
A9: y-o-y growth % | C9: =(C8-B8)/B8 -> 0.049293733 | D9: =(D8-C8)/C8 -> 0.029585207 | E9: =(E8-D8)/D8 -> 0.32074556 | F9: =(F8-E8)/E8 -> 0.40646821 | G9: =(G8-F8)/F8 -> 0.23109485 | H9: =(H8-G8)/G8 -> 0.16402768 | I9: =VLOOKUP($B$3,$I$3:$K$5,3,FALSE()) -> 0.0687 | J9: =VLOOKUP($B$3,$I$3:$K$5,3,FALSE()) -> 0.0687 | K9: =VLOOKUP($B$3,$I$3:$K$5,3,FALSE()) -> 0.0687 | L9: =VLOOKUP($B$3,$I$3:$K$5,3,FALSE()) -> 0.0687 | M9: =VLOOKUP($B$3,$I$3:$K$5,3,FALSE()) -> 0.0687
A11: Other Income | B11: =FS!B7 -> 178.5 | C11: =FS!C7 -> 146 | D11: =FS!D7 -> 181 | E11: =FS!E7 -> 246 | F11: =FS!F7 -> 299 | G11: =FS!G7 -> 510 | H11: =FS!H7 -> 493 | I11: =I8*I12 -> 520.03621 | J11: =J8*J12 -> 570.50048 | K11: =K8*K12 -> 610.59588 | L11: =L8*L12 -> 671.26869 | M11: =M8*M12 -> 695.34484
A12: % of Revenue | B12: =B11/B8 -> 0.0093602664 | C12: =C11/C8 -> 0.0072963518 | D12: =D11/D8 -> 0.0087855548 | E12: =E11/E8 -> 0.0090407938 | F12: =F11/F8 -> 0.0078129083 | G12: =G11/G8 -> 0.010824808 | H12: =H11/H8 -> 0.0089894606 | I12: =AVERAGE(B12:H12) -> 0.0088728777 | J12: =AVERAGE(I12,H12,G12,F12,E12) -> 0.0091081697 | K12: =AVERAGE(J12,I12,H12,G12,F12) -> 0.0091216448 | L12: =AVERAGE(K12,J12,I12,H12,G12) -> 0.0093833921 | M12: =AVERAGE(L12,K12,J12,I12,H12) -> 0.009095109
A14: Cost of Goods Sold | B14: =FS!B12+FS!B13+FS!B14 -> 13987.18 | C14: =FS!C12+FS!C13+FS!C14 -> 14512 | D14: =FS!D12+FS!D13+FS!D14 -> 15769 | E14: =FS!E12+FS!E13+FS!E14 -> 20658 | F14: =FS!F12+FS!F13+FS!F14 -> 29046 | G14: =FS!G12+FS!G13+FS!G14 -> 36942 | H14: =FS!H12+FS!H13+FS!H14 -> 43740 | I14: =I8*I15 -> 45308.246 | J14: =J8*J15 -> 48516.629 | K14: =K8*K15 -> 52055.53 | L14: =L8*L15 -> 55898.98 | M14: =M8*M15 -> 59697.817
A15: % of Revenue | B15: =B14/B8 -> 0.73346628 | C15: =C14/C8 -> 0.72523738 | D15: =D14/D8 -> 0.76541113 | E15: =E14/E8 -> 0.75920617 | F15: =F14/F8 -> 0.7589757 | G15: =G14/G8 -> 0.78409814 | H15: =H14/H8 -> 0.79756391 | I15: =AVERAGE(H15,G15,F15,E15,D15) -> 0.77305101 | J15: =AVERAGE(I15,H15,G15,F15,E15) -> 0.77457899 | K15: =AVERAGE(J15,I15,H15,G15,F15) -> 0.77765355 | L15: =AVERAGE(K15,J15,I15,H15,G15) -> 0.78138912 | M15: =AVERAGE(L15,K15,J15,I15,H15) -> 0.78084732
A17: Employee Benefit Expenses | B17: =FS!B15 -> 878.79 | C17: =FS!C15 -> 1040 | D17: =FS!D15 -> 911 | E17: =FS!E15 -> 1143 | F17: =FS!F15 -> 1362 | G17: =FS!G15 -> 1503 | H17: =FS!H15 -> 1717 | I17: =I8*I18 -> 2168.842 | J17: =J8*J18 -> 2227.4683 | K17: =K8*K18 -> 2294.2163 | L17: =L8*L18 -> 2432.9985 | M17: =M8*M18 -> 2632.3864
A18: % of Revenue | B18: =B17/B8 -> 0.046082401 | C18: =C17/C8 -> 0.051974013 | D18: =D17/D8 -> 0.044219008 | E18: =E17/E8 -> 0.042006615 | F18: =F17/F8 -> 0.035589234 | G18: =G17/G8 -> 0.031901346 | H18: =H17/H8 -> 0.031308122 | I18: =AVERAGE(H18,G18,F18,E18,D18) -> 0.037004865 | J18: =AVERAGE(I18,H18,G18,F18,E18) -> 0.035562036 | K18: =AVERAGE(J18,I18,H18,G18,F18) -> 0.034273121 | L18: =AVERAGE(K18,J18,I18,H18,G18) -> 0.034009898 | M18: =AVERAGE(L18,K18,J18,I18,H18) -> 0.034431608
A20: Finance Cost | B20: =FS!B16 -> 44.45 | C20: =FS!C16 -> 149 | D20: =FS!D16 -> 181 | E20: =FS!E16 -> 195 | F20: =FS!F16 -> 240 | G20: =FS!G16 -> 480 | H20: =FS!H16 -> 767 | I20: =I8*I21 -> 543.86181 | J20: =J8*J21 -> 587.41151 | K20: =K8*K21 -> 657.37625 | L20: =L8*L21 -> 753.31939 | M20: =M8*M21 -> 810.30624
A21: % of Revenue | B21: =B20/B8 -> 0.0023308899 | C21: =C20/C8 -> 0.0074462769 | D21: =D20/D8 -> 0.0087855548 | E21: =E20/E8 -> 0.0071664829 | F21: =F20/F8 -> 0.0062712307 | G21: =G20/G8 -> 0.010188055 | H21: =H20/H8 -> 0.013985631 | I21: =AVERAGE(H21,G21,F21,E21,D21) -> 0.0092793909 | J21: =AVERAGE(I21,H21,G21,F21,E21) -> 0.0093781581 | K21: =AVERAGE(J21,I21,H21,G21,F21) -> 0.0098204931 | L21: =AVERAGE(K21,J21,I21,H21,G21) -> 0.010530346 | M21: =AVERAGE(L21,K21,J21,I21,H21) -> 0.010598804
A23: Other Expenses | B23: =FS!B18 -> 2201.79 | C23: =FS!C18 -> 2040 | D23: =FS!D18 -> 2221 | E23: =FS!E18 -> 2130 | F23: =FS!F18 -> 3092 | G23: =FS!G18 -> 3645 | H23: =FS!H18 -> 4093 | I23: =I8*I24 -> 4910.0534 | J23: =J8*J24 -> 4946.3504 | K23: =K8*K24 -> 5295.3965 | L23: =L8*L24 -> 5635.0557 | M23: =M8*M24 -> 6043.6613
A24: % of Revenue | B24: =B23/B8 -> 0.11545849 | C24: =C23/C8 -> 0.10194903 | D24: =D23/D8 -> 0.10780507 | E24: =E23/E8 -> 0.078280044 | F24: =F23/F8 -> 0.080794356 | G24: =G23/G8 -> 0.077365539 | H24: =H23/H8 -> 0.074632581 | I24: =AVERAGE(H24,G24,F24,E24,D24) -> 0.083775517 | J24: =AVERAGE(I24,H24,G24,F24,E24) -> 0.078969607 | K24: =AVERAGE(J24,I24,H24,G24,F24) -> 0.07910752 | L24: =AVERAGE(K24,J24,I24,H24,G24) -> 0.078770153 | M24: =AVERAGE(L24,K24,J24,I24,H24) -> 0.079051076
A26: Current Tax | B26: =FS!B26 -> 602.01 | C26: =FS!C26 -> 552 | D26: =FS!D26 -> 351 | E26: =FS!E26 -> 779 | F26: =FS!F26 -> 1140 | G26: =FS!G26 -> 1072 | H26: =FS!H26 -> 1117 | I26: =I27*(I8+I11-I14-I17-I20-I23-I57) -> 1423.2567 | J26: =J27*(J8+J11-J14-J17-J20-J23-J57) -> 1581.6823 | K26: =K27*(K8+K11-K14-K17-K20-K23-K57) -> 1644.2315 | L26: =L27*(L8+L11-L14-L17-L20-L23-L57) -> 1685.2942 | M26: =M27*(M8+M11-M14-M17-M20-M23-M57) -> 1788.2665
A27: Effective Tax Rate (% of EBT) | B27: =B26/FS!B24 -> 0.31234791 | C27: =C26/FS!C24 -> 0.26223278 | D27: =D26/FS!D24 -> 0.28467153 | E27: =E26/FS!E24 -> 0.26568895 | F27: =F26/FS!F24 -> 0.25531915 | G27: =G26/FS!G24 -> 0.23268939 | H27: =H26/FS!H24 -> 0.24927472 | I27: 0.25168 | J27: 0.25168 | K27: 0.25168 | L27: 0.25168 | M27: 0.25168
A29: Dividend | C29: =FS!C29-(FS!C40-FS!B40) -> 873.94 | D29: =FS!D29-(FS!D40-FS!C40) -> 149 | E29: =FS!E29-(FS!E40-FS!D40) -> 360 | F29: =FS!F29-(FS!F40-FS!E40) -> 712 | G29: =FS!G29-(FS!G40-FS!F40) -> 1081 | H29: =FS!H29-(FS!H40-FS!G40) -> 981 | I29: =I30*((I8+I11-I14-I17-I20-I23-I57)-I26) -> 971.47167 | J29: =J30*((J8+J11-J14-J17-J20-J23-J57)-J26) -> 1135.7307 | K29: =K30*((K8+K11-K14-K17-K20-K23-K57)-K26) -> 1255.3084 | L29: =L30*((L8+L11-L14-L17-L20-L23-L57)-L26) -> 1329.9034 | M29: =M30*((M8+M11-M14-M17-M20-M23-M57)-M26) -> 1369.0292
A30: Dividend Payout Ratio | C30: =C29/FS!C29 -> 0.57609756 | D30: =D29/FS!D29 -> 0.16989738 | E30: =E29/FS!E29 -> 0.16513761 | F30: =F29/FS!F29 -> 0.21362136 | G30: =G29/FS!G29 -> 0.30502257 | H30: =H29/FS!H29 -> 0.29415292 | I30: =AVERAGE(H30,G30,F30,E30,D30) -> 0.22956637 | J30: =AVERAGE(I30,H30,G30,F30,E30) -> 0.24150017 | K30: =AVERAGE(J30,I30,H30,G30,F30) -> 0.25677268 | L30: =AVERAGE(K30,J30,I30,H30,G30) -> 0.26540294 | M30: =AVERAGE(L30,K30,J30,I30,H30) -> 0.25747902
A32: BALANCE SHEET ASSUMPTIONS
A33: Particulars | B33: 2019 Actual | C33: 2020 Actual | D33: 2021 Actual | E33: 2022 Actual | F33: 2023 Actual | G33: 2024 Actual | H33: 2025 Forecast | I33: 2026 Forecast | J33: 2027 Forecast | K33: 2028 Forecast | L33: 2029 Forecast | M33: 2030 Forecast
A34: Trade Receivables | B34: =FS!B71 -> 358.23 | C34: =FS!C71 -> 214 | D34: =FS!D71 -> 291 | E34: =FS!E71 -> 495 | F34: =FS!F71 -> 908 | G34: =FS!G71 -> 937 | H34: =FS!H71 -> 984 | I34: =(I35/365)*I8 -> 1100.3753 | J34: =(J35/365)*J8 -> 1234.2202 | K34: =(K35/365)*K8 -> 1339.2638 | L34: =(L35/365)*L8 -> 1378.0613 | M34: =(M35/365)*M8 -> 1463.184
A35: Debtor Days (Days Receivable) | B35: =B34*365/B8 -> 6.8565367 | C35: =C34*365/C8 -> 3.9035482 | D35: =D34*365/D8 -> 5.1555674 | E35: =E34*365/E8 -> 6.6400221 | F35: =F34*365/F8 -> 8.660047 | G35: =G34*365/G8 -> 7.259095 | H35: =H34*365/H8 -> 6.5489953 | I35: =AVERAGE(H35,G35,F35,E35,D35) -> 6.8527454 | J35: =AVERAGE(I35,H35,G35,F35,E35) -> 7.1921809 | K35: =AVERAGE(J35,I35,H35,G35,F35) -> 7.3026127 | L35: =AVERAGE(K35,J35,I35,H35,G35) -> 7.0311259 | M35: =AVERAGE(L35,K35,J35,I35,H35) -> 6.985532
A37: Inventory | B37: =FS!B70 -> 6719.18 | C37: =FS!C70 -> 7741 | D37: =FS!D70 -> 7984 | E37: =FS!E70 -> 12787 | F37: =FS!F70 -> 14952 | G37: =FS!G70 -> 16874 | H37: =FS!H70 -> 24517 | I37: =(I38/365)*I14 -> 24079.988 | J37: =(J38/365)*J14 -> 26029.289 | K37: =(K38/365)*K14 -> 27069.18 | L37: =(L38/365)*L14 -> 29126.335 | M37: =(M38/365)*M14 -> 31873.242
A38: Inventory Days (Days Inventory) | B38: =B37*365/B14 -> 175.33918 | C38: =C37*365/C14 -> 194.69853 | D38: =D37*365/D14 -> 184.80309 | E38: =E37*365/E14 -> 225.92966 | F38: =F37*365/F14 -> 187.89093 | G38: =G37*365/G14 -> 166.72108 | H38: =H37*365/H14 -> 204.58859 | I38: =AVERAGE(H38,G38,F38,E38,D38) -> 193.98667 | J38: =AVERAGE(I38,H38,G38,F38,E38) -> 195.82339 | K38: =AVERAGE(J38,I38,H38,G38,F38) -> 189.80213 | L38: =AVERAGE(K38,J38,I38,H38,G38) -> 190.18437 | M38: =AVERAGE(L38,K38,J38,I38,H38) -> 194.87703
A40: Trade Payables | B40: =FS!B50 -> 772.34 | C40: =FS!C50 -> 510 | D40: =FS!D50 -> 695 | E40: =FS!E50 -> 1055 | F40: =FS!F50 -> 965 | G40: =FS!G50 -> 943 | H40: =FS!H50 -> 1472 | I40: =(I41/365)*I14 -> 1699.4823 | J40: =(J41/365)*J14 -> 1756.1294 | K40: =(K41/365)*K14 -> 1729.3769 | L40: =(L41/365)*L14 -> 1857.0475 | M40: =(M41/365)*M14 -> 2075.1254
A41: Creditor Days (Days Payable) | B41: =B40*365/B14 -> 20.154463 | C41: =C40*365/C14 -> 12.827315 | D41: =D40*365/D14 -> 16.086943 | E41: =E40*365/E14 -> 18.640478 | F41: =F40*365/F14 -> 12.126455 | G41: =G40*365/G14 -> 9.3171729 | H41: =H40*365/H14 -> 12.283493 | I41: =AVERAGE(H41,G41,F41,E41,D41) -> 13.690908 | J41: =AVERAGE(I41,H41,G41,F41,E41) -> 13.211701 | K41: =AVERAGE(J41,I41,H41,G41,F41) -> 12.125946 | L41: =AVERAGE(K41,J41,I41,H41,G41) -> 12.125844 | M41: =AVERAGE(L41,K41,J41,I41,H41) -> 12.687579
A43: Other Current Liabilities | B43: =FS!B51 -> 2042.43 | C43: =FS!C51 -> 2314 | D43: =FS!D51 -> 2123 | E43: =FS!E51 -> 2815 | F43: =FS!F51 -> 3862 | G43: =FS!G51 -> 4425 | H43: =FS!H51 -> 5203 | I43: =I8*I44 -> 5816.5511 | J43: =J8*J44 -> 6168.4692 | K43: =K8*K44 -> 6525.6572 | L43: =L8*L44 -> 6924.9197 | M43: =M8*M44 -> 7444.6909
A44: % of Revenue | B44: =B43/B8 -> 0.1071019 | C44: =C43/C8 -> 0.11564218 | D44: =D43/D8 -> 0.10304825 | E44: =E43/E8 -> 0.10345461 | F44: =F43/F8 -> 0.10091455 | G44: =G43/G8 -> 0.093921127 | H44: =H43/H8 -> 0.094872543 | I44: =AVERAGE(H44,G44,F44,E44,D44) -> 0.099242217 | J44: =AVERAGE(I44,H44,G44,F44,E44) -> 0.098481011 | K44: =AVERAGE(J44,I44,H44,G44,F44) -> 0.097486291 | L44: =AVERAGE(K44,J44,I44,H44,G44) -> 0.096800638 | M44: =AVERAGE(L44,K44,J44,I44,H44) -> 0.09737654
A46: Other Current Assets | B46: =FS!B74 -> 222.6 | C46: =FS!C74 -> 263 | D46: =FS!D74 -> 275 | E46: =FS!E74 -> 267 | F46: =FS!F74 -> 296 | G46: =FS!G74 -> 412 | H46: =FS!H74 -> 430 | I46: =I8*I47 -> 556.56608 | J46: =J8*J47 -> 546.54646 | K46: =K8*K47 -> 569.54388 | L46: =L8*L47 -> 619.74353 | M46: =M8*M47 -> 661.07215
A47: % of Revenue | B47: =B46/B8 -> 0.011672803 | C47: =C46/C8 -> 0.013143428 | D47: =D46/D8 -> 0.013348219 | E47: =E46/E8 -> 0.0098125689 | F47: =F46/F8 -> 0.0077345179 | G47: =G46/G8 -> 0.0087447468 | H47: =H46/H8 -> 0.007840706 | I47: =AVERAGE(H47,G47,F47,E47,D47) -> 0.0094961516 | J47: =AVERAGE(I47,H47,G47,F47,E47) -> 0.0087257383 | K47: =AVERAGE(J47,I47,H47,G47,F47) -> 0.0085083721 | L47: =AVERAGE(K47,J47,I47,H47,G47) -> 0.008663143 | M47: =AVERAGE(L47,K47,J47,I47,H47) -> 0.0086468222
A49: Short-Term Loans & Advances | B49: =FS!B73 -> 715.03 | C49: =FS!C73 -> 886 | D49: =FS!D73 -> 720 | E49: =FS!E73 -> 1766 | F49: =FS!F73 -> 1595 | G49: =FS!G73 -> 2030 | H49: =FS!H73 -> 2044 | I49: =I8*I50 -> 2600.9309 | J49: =J8*J50 -> 2897.7356 | K49: =K8*K50 -> 2847.2659 | L49: =L8*L50 -> 3055.1423 | M49: =M8*M50 -> 3259.2142
A50: % of Revenue | B50: =B49/B8 -> 0.037495077 | C50: =C49/C8 -> 0.044277861 | D50: =D49/D8 -> 0.034948063 | E50: =E49/E8 -> 0.064902609 | F50: =F49/F8 -> 0.041677554 | G50: =G49/G8 -> 0.043086981 | H50: =H49/H8 -> 0.037270705 | I50: =AVERAGE(H50,G50,F50,E50,D50) -> 0.044377182 | J50: =AVERAGE(I50,H50,G50,F50,E50) -> 0.046263006 | K50: =AVERAGE(J50,I50,H50,G50,F50) -> 0.042535086 | L50: =AVERAGE(K50,J50,I50,H50,G50) -> 0.042706592 | M50: =AVERAGE(L50,K50,J50,I50,H50) -> 0.042630514
A52: PPE SCHEDULE ASSUMPTIONS
A53: Particulars | B53: 2019 Actual | C53: 2020 Actual | D53: 2021 Actual | E53: 2022 Actual | F53: 2023 Actual | G53: 2024 Actual | H53: 2025 Forecast | I53: 2026 Forecast | J53: 2027 Forecast | K53: 2028 Forecast | L53: 2029 Forecast | M53: 2030 Forecast
A54: Capital Expenditure (Capex) | C54: =FS!C58-FS!B58+FS!C17 -> 397.96 | D54: =FS!D58-FS!C58+FS!D17 -> 262 | E54: =FS!E58-FS!D58+FS!E17 -> 333 | F54: =FS!F58-FS!E58+FS!F17 -> 420 | G54: =FS!G58-FS!F58+FS!G17 -> 759 | H54: =FS!H58-FS!G58+FS!H17 -> 631 | I54: =I8*I55 -> 762.50965 | J54: =J8*J55 -> 834.26907 | K54: =K8*K55 -> 904.49963 | L54: =L8*L55 -> 1008.5715 | M54: =M8*M55 -> 1028.2118
...

Sheet FS
A1: Income Statement | I1: FORECASTED
A2: Year | B2: 2019 | C2: 2020 | D2: 2021 | E2: 2022 | F2: 2023 | G2: 2024 | H2: 2025 | I2: 2026 | J2: 2027 | K2: 2028 | L2: 2029 | M2: 2030
A3: REVENUE
A4: Revenue From Operations(Gross) | B4: 19069.97 | C4: 20010 | D4: 20602 | E4: 27210 | F4: 38270 | G4: 47114 | H4: 54842 | I4: =Assumptions!I8 -> 58609.645 | J4: =Assumptions!J8 -> 62636.128 | K4: =Assumptions!K8 -> 66939.23 | L4: =Assumptions!L8 -> 71537.955 | M4: =Assumptions!M8 -> 76452.613
A5: Less: Excise Duty | B5: 0 | C5: 0 | D5: 0 | E5: 0 | F5: 0 | G5: 0 | H5: 0 | I5: 0 | J5: 0 | K5: 0 | L5: 0 | M5: 0
A6: Revenue From Operations(Net) | B6: 19069.97 | C6: 20010 | D6: 20602 | E6: 27210 | F6: 38270 | G6: 47114 | H6: 54842 | I6: =Assumptions!I8 -> 58609.645 | J6: =Assumptions!J8 -> 62636.128 | K6: =Assumptions!K8 -> 66939.23 | L6: =Assumptions!L8 -> 71537.955 | M6: =Assumptions!M8 -> 76452.613
A7: Other Income | B7: 178.5 | C7: 146 | D7: 181 | E7: 246 | F7: 299 | G7: 510 | H7: 493 | I7: =Assumptions!I11 -> 520.03621 | J7: =Assumptions!J11 -> 570.50048 | K7: =Assumptions!K11 -> 610.59588 | L7: =Assumptions!L11 -> 671.26869 | M7: =Assumptions!M11 -> 695.34484
A8: Total Revenue | B8: 19248.47 | C8: 20156 | D8: 20783 | E8: 27456 | F8: 38569 | G8: 47624 | H8: 55335 | I8: =I6+I7 -> 59129.682 | J8: =J6+J7 -> 63206.629 | K8: =K6+K7 -> 67549.826 | L8: =L6+L7 -> 72209.224 | M8: =M6+M7 -> 77147.958
A9: COGS | B9: =Assumptions!B14 -> 13987.18 | C9: =Assumptions!C14 -> 14512 | D9: =Assumptions!D14 -> 15769 | E9: =Assumptions!E14 -> 20658 | F9: =Assumptions!F14 -> 29046 | G9: =Assumptions!G14 -> 36942 | H9: =Assumptions!H14 -> 43740 | I9: =Assumptions!I14 -> 45308.246 | ... M9: =Assumptions!M14 -> 59697.817
A10: GROSS MARGINS | B10: =B8-B9 -> 5261.29 | C10: =C8-C9 -> 5644 | D10: =D8-D9 -> 5014 | E10: =E8-E9 -> 6798 | F10: =F8-F9 -> 9523 | G10: =G8-G9 -> 10682 | H10: =H8-H9 -> 11595 | I10: =I8-I9 -> 13821.436 | ... M10: =M8-M9 -> 17450.14
A11: EXPENSES
A12: Cost of Materials Consumed | B12: 11822.04 | C12: 12489 | D12: 13143 | E12: 20939 | F12: 25085 | G12: 33556 | H12: 43905
A13: Purchases of Stock-in-Trade | B13: 2828.92 | C13: 2859 | D13: 2462 | E13: 4187 | F13: 5438 | G13: 5535 | H13: 6372
A14: Changes in Inventories of Finished Goods, Work-in-Progress and Stock-in-Trade | B14: -663.78 | C14: -836 | D14: 164 | E14: -4468 | F14: -1477 | G14: -2149 | H14: -6537
A15: Employee Benefits Expenses | B15: 878.79 | C15: 1040 | D15: 911 | E15: 1143 | F15: 1362 | G15: 1503 | H15: 1717 | I15: =Assumptions!I17 -> 2168.842 | J15: =Assumptions!J17 -> 2227.4683 | K15: =Assumptions!K17 -> 2294.2163 | L15: =Assumptions!L17 -> 2432.9985 | M15: =Assumptions!M17 -> 2632.3864
A16: Finance Costs | B16: 44.45 | C16: 149 | D16: 181 | E16: 195 | F16: 240 | G16: 480 | H16: 767 | I16: =Assumptions!I20 -> 543.86181 | J16: =Assumptions!J20 -> 587.41151 | K16: =Assumptions!K20 -> 657.37625 | L16: =Assumptions!L20 -> 753.31939 | M16: =Assumptions!M20 -> 810.30624
A17: Depreciation and Amortization Expenses | B17: 138.89 | C17: 310 | D17: 331 | E17: 347 | F17: 364 | G17: 447 | H17: 537 | I17: =Assumptions!I57 -> 543.65395 | J17: =Assumptions!J57 -> 644.2721 | K17: =Assumptions!K57 -> 714.28275 | L17: =Assumptions!L57 -> 792.69204 | M17: =Assumptions!M57 -> 858.46802
A18: Other Expenses | B18: 2201.79 | C18: 2040 | D18: 2221 | E18: 2130 | F18: 3092 | G18: 3645 | H18: 4093 | I18: =Assumptions!I23 -> 4910.0534 | J18: =Assumptions!J23 -> 4946.3504 | K18: =Assumptions!K23 -> 5295.3965 | L18: =Assumptions!L23 -> 5635.0557 | M18: =Assumptions!M23 -> 6043.6613
A19: Total Expenses | B19: =B9+B15+B16+B17+B18 -> 17251.1 | C19: =C9+C15+C16+C17+C18 -> 18051 | D19: =D9+D15+D16+D17+D18 -> 19413 | E19: =E9+E15+E16+E17+E18 -> 24473 | F19: =F9+F15+F16+F17+F18 -> 34104 | G19: =G9+G15+G16+G17+G18 -> 43017 | H19: =H9+H15+H16+H17+H18 -> 50854 | I19: =I9+I15+I16+I17+I18 -> 53474.657 | ... M19: =M9+M15+M16+M17+M18 -> 70042.639
A20: Profit before Exceptional and Extraordinary Items and Tax | B20: =B8-B19 -> 1997.37 | C20: =C8-C19 -> 2105 | D20: =D8-D19 -> 1370 | E20: =E8-E19 -> 2983 | F20: =F8-F19 -> 4465 | G20: =G8-G19 -> 4607 | H20: =H8-H19 -> 4481 | I20: =I8-I19 -> 5655.0249 | ... M20: =M8-M19 -> 7105.3181
A21: Exceptional Items | B21: -70 | C21: 0 | D21: -137 | E21: -51 | F21: 0 | G21: 0 | H21: 0 | I21: 0 | J21: 0 | K21: 0 | L21: 0 | M21: 0
A22: Profit before Extraordinary Items and Tax | B22: =B20+B21 -> 1927.37 | C22: =C20+C21 -> 2105 | D22: =D20+D21 -> 1233 | E22: =E20+E21 -> 2932 | F22: =F20+F21 -> 4465 | G22: =G20+G21 -> 4607 | H22: =H20+H21 -> 4481 | I22: =I20+I21 -> 5655.0249 | ... M22: =M20+M21 -> 7105.3181
A23: Extraordinary Items | B23: 0 | C23: 0 | D23: 0 | E23: 0 | F23: 0 | G23: 0 | H23: 0 | I23: 0 | J23: 0 | K23: 0 | L23: 0 | M23: 0
A24: Profit before Tax | B24: =B22+B23 -> 1927.37 | C24: =C22+C23 -> 2105 | D24: =D22+D23 -> 1233 | E24: =E22+E23 -> 2932 | F24: =F22+F23 -> 4465 | G24: =G22+G23 -> 4607 | H24: =H22+H23 -> 4481 | I24: =I22+I23 -> 5655.0249 | ... M24: =M22+M23 -> 7105.3181
A25: Tax Expenses | B25: =B26+B27 -> 553.01 | C25: =C26+C27 -> 588 | D25: =D26+D27 -> 356 | E25: =E26+E27 -> 752 | F25: =F26+F27 -> 1132 | G25: =G26+G27 -> 1063 | H25: =H26+H27 -> 1146 | I25: =I26+I27 -> 1423.2567 | ... M25: =M26+M27 -> 1788.2665
A26: Current Tax | B26: 602.01 | C26: 552 | D26: 351 | E26: 779 | F26: 1140 | G26: 1072 | H26: 1117 | I26: =Assumptions!I26 -> 1423.2567 | J26: =Assumptions!J26 -> 1581.6823 | K26: =Assumptions!K26 -> 1644.2315 | L26: =Assumptions!L26 -> 1685.2942 | M26: =Assumptions!M26 -> 1788.2665
A27: Deferred Tax | B27: -49 | C27: 36 | D27: 5 | E27: -27 | F27: -8 | G27: -9 | H27: 29 | I27: 0 | J27: 0 | K27: 0 | L27: 0 | M27: 0
A28: Profit/(Loss) for the period from Continuing Operations | B28: =B24-B25 -> 1374.36 | C28: =C24-C25 -> 1517 | D28: =D24-D25 -> 877 | E28: =E24-E25 -> 2180 | F28: =F24-F25 -> 3333 | G28: =G24-G25 -> 3544 | H28: =H24-H25 -> 3335 | I28: =I24-I25 -> 4231.7682 | ... M28: =M24-M25 -> 5317.0517
A29: Profit/(Loss) for the period | B29: =B28 -> 1374.36 | C29: =C28 -> 1517 | D29: =D28 -> 877 | E29: =E28 -> 2180 | F29: =F28 -> 3333 | G29: =G28 -> 3544 | H29: =H28 -> 3335 | I29: =I28 -> 4231.7682 | ... M29: =M28 -> 5317.0517
A30: Basic EPS | B30: 15.48 | C30: 17.09 | D30: 9.88 | E30: 24.56 | F30: 37.54 | G30: 39.94 | H30: 37.6 | I30: =I29/(H29/H30) -> 47.71049 | J30: =J29/(H29/H30) -> 53.021245 | K30: =K29/(H29/H30) -> 55.118022 | L30: =L29/(H29/H30) -> 56.494526 | M30: =M29/(H29/H30) -> 59.94637
A31: Diluted EPS | B31: 15.48 | C31: 17.09 | D31: 9.88 | E31: 24.56 | F31: 37.54 | G31: 39.92 | H31: 37.58 | I31: =I30 -> 47.71049 | J31: =J30 -> 53.021245 | K31: =K30 -> 55.118022 | L31: =L30 -> 56.494526 | M31: =M30 -> 59.94637
A32: Book Value | B32: 69.63 | C32: 76.87 | D32: 85.07 | E32: 105.57 | F32: 134.76 | G32: 162.44 | H32: 188.89 | I32: =I41/(H29/H30) -> 226.29108 | J32: =J41/(H29/H30) -> 266.50768 | K32: =K41/(H29/H30) -> 307.4729 | L32: =L41/(H29/H30) -> 348.97362 | M32: =M41/(H29/H30) -> 393.48505
A33: Contingent Liabilities & Commitments | B33: 491.7 | C33: 88 | D33: 474 | E33: 2224 | F33: 2846 | G33: 2172 | H33: 702
A35: Balance Sheet | I35: FORECASTED
A36: Particulars | B36: 2019 | C36: 2020 | D36: 2021 | E36: 2022 | F36: 2023 | G36: 2024 | H36: 2025 | I36: 2026 | J36: 2027 | K36: 2028 | L36: 2029 | M36: 2030
A37: Shareholder's Funds
A38: Share Capital | B38: 88.78 | C38: 89 | D38: 89 | E38: 89 | F38: 89 | G38: 89 | H38: 89 | I38: =H38 -> 89 | J38: =H38 -> 89 | K38: =H38 -> 89 | L38: =H38 -> 89 | M38: =H38 -> 89
A39: Ordinary Capital | B39: 88.78 | C39: 88.78 | D39: 88.78 | E39: 88.78 | F39: 89 | G39: 89 | H39: 89 | I39: =H39 -> 89 | J39: =H39 -> 89 | K39: =H39 -> 89 | L39: =H39 -> 89 | M39: =H39 -> 89
A40: Reserves and Surplus | B40: 6092.94 | C40: 6736 | D40: 7464 | E40: 9284 | F40: 11905 | G40: 14368 | H40: 16722 | I40: =H40+I29-Assumptions!I29 -> 19982.297 | J40: =I40+J29-Assumptions!J29 -> 23549.381 | K40: =J40+K29-Assumptions!K29 -> 27182.865 | L40: =K40+L29-Assumptions!L29 -> 30863.846 | M40: =L40+M29-Assumptions!M29 -> 34811.869
A41: Total Shareholder's Fund | B41: 6181.72 | C41: 6825 | D41: 7553 | E41: 9373 | F41: 11994 | G41: 14457 | H41: 16811 | I41: =I38+I40 -> 20071.297 | J41: =J38+J40 -> 23638.381 | K41: =K38+K40 -> 27271.865 | L41: =L38+L40 -> 30952.846 | M41: =M38+M40 -> 34900.869
...

Sheet CFS
A1: CASH FLOW STATEMENT - TITAN COMPANY LIMITED | I1: FORECASTED
A2: Particulars | B2: 2019 | C2: 2020 | D2: 2021 | E2: 2022 | F2: 2023 | G2: 2024 | H2: 2025 | I2: 2026 | J2: 2027 | K2: 2028 | L2: 2029 | M2: 2030
A3: (INR in Cr.)
A4: A. CASH FLOW FROM OPERATING ACTIVITIES
A5: Profit before Tax | B5: 1927.37 | C5: 2105 | D5: 1233 | E5: 2932 | F5: 4465 | G5: 4607 | H5: 4481 | I5: =FS!I24 -> 5655.0249 | J5: =FS!J24 -> 6284.4975 | K5: =FS!K24 -> 6533.0242 | L5: =FS!L24 -> 6696.1783 | M5: =FS!M24 -> 7105.3181
A6: Add: Depreciation & Amortisation | B6: 138.89 | C6: 310 | D6: 331 | E6: 347 | F6: 364 | G6: 447 | H6: 537 | I6: =FS!I17 -> 543.65395 | J6: =FS!J17 -> 644.2721 | K6: =FS!K17 -> 714.28275 | L6: =FS!L17 -> 792.69204 | M6: =FS!M17 -> 858.46802
A7: Add: Finance Cost | B7: 44.45 | C7: 149 | D7: 181 | E7: 195 | F7: 240 | G7: 480 | H7: 767 | I7: =FS!I16 -> 543.86181 | J7: =FS!J16 -> 587.41151 | K7: =FS!K16 -> 657.37625 | L7: =FS!L16 -> 753.31939 | M7: =FS!M16 -> 810.30624
A8: Cash Flow before Working Capital Changes | B8: =B5+B6+B7 -> 2110.71 | C8: =C5+C6+C7 -> 2564 | D8: =D5+D6+D7 -> 1745 | E8: =E5+E6+E7 -> 3474 | F8: =F5+F6+F7 -> 5069 | G8: =G5+G6+G7 -> 5534 | H8: =H5+H6+H7 -> 5785 | I8: =I5+I6+I7 -> 6742.5406 | ... M8: =M5+M6+M7 -> 8774.0924
A9: Changes in Working Capital:
A10: (Increase)/Decrease in Inventories | C10: -1021.82 | D10: -243 | E10: -4803 | F10: -2165 | G10: -1922 | H10: -7643 | I10: =-(Assumptions!I37-FS!H70) -> 437.0116 | J10: =-(Assumptions!J37-FS!I70) -> -1949.3008 | K10: =-(Assumptions!K37-FS!J70) -> -1039.8904 | L10: =-(Assumptions!L37-FS!K70) -> -2057.1557 | M10: =-(Assumptions!M37-FS!L70) -> -2746.9069
A11: (Increase)/Decrease in Trade Receivables | C11: 144.23 | D11: -77 | E11: -204 | F11: -413 | G11: -29 | H11: -47 | I11: =-(Assumptions!I34-FS!H71) -> -116.37527 | J11: =-(Assumptions!J34-FS!I71) -> -133.84491 | K11: =-(Assumptions!K34-FS!J71) -> -105.04358 | L11: =-(Assumptions!L34-FS!K71) -> -38.797516 | M11: =-(Assumptions!M34-FS!L71) -> -85.122764
A12: (Increase)/Decrease in Other Current Assets | C12: -40.4 | D12: -12 | E12: 8 | F12: -29 | G12: -116 | H12: -18 | I12: =-(Assumptions!I46-FS!H74) -> -126.56608 | J12: =-(Assumptions!J46-FS!I74) -> 10.019622 | K12: =-(Assumptions!K46-FS!J74) -> -22.99742 | L12: =-(Assumptions!L46-FS!K74) -> -50.199654 | M12: =-(Assumptions!M46-FS!L74) -> -41.328616
A13: (Increase)/Decrease in ST Loans & Advances | C13: -170.97 | D13: 166 | E13: -1046 | F13: 171 | G13: -435 | H13: -14 | I13: =-(Assumptions!I49-FS!H73) -> -556.93093 | J13: =-(Assumptions!J49-FS!I73) -> -296.80466 | K13: =-(Assumptions!K49-FS!J73) -> 50.4697 | L13: =-(Assumptions!L49-FS!K73) -> -207.87638 | M13: =-(Assumptions!M49-FS!L73) -> -204.07193
A14: Increase/(Decrease) in Trade Payables | C14: -262.34 | D14: 185 | E14: 360 | F14: -90 | G14: -22 | H14: 529 | I14: =Assumptions!I40-FS!H50 -> 227.4823 | J14: =Assumptions!J40-FS!I50 -> 56.647058 | K14: =Assumptions!K40-FS!J50 -> -26.752502 | L14: =Assumptions!L40-FS!K50 -> 127.67064 | M14: =Assumptions!M40-FS!L50 -> 218.07788
A15: Increase/(Decrease) in Other Current Liabilities | C15: 271.57 | D15: -191 | E15: 692 | F15: 1047 | G15: 563 | H15: 778 | I15: =Assumptions!I43-FS!H51 -> 613.55115 | J15: =Assumptions!J43-FS!I51 -> 351.91806 | K15: =Assumptions!K43-FS!J51 -> 357.18802 | L15: =Assumptions!L43-FS!K51 -> 399.26245 | M15: =Assumptions!M43-FS!L51 -> 519.7712
A16: Net Changes in Working Capital | B16: =SUM(B10:B15) -> 0 | C16: =SUM(C10:C15) -> -1079.73 | D16: =SUM(D10:D15) -> -172 | E16: =SUM(E10:E15) -> -4993 | F16: =SUM(F10:F15) -> -1479 | G16: =SUM(G10:G15) -> -1961 | H16: =SUM(H10:H15) -> -6415 | I16: =SUM(I10:I15) -> 478.17276 | ... M16: =SUM(M10:M15) -> -2339.5812
A17: Less: Tax Paid | B17: 602.01 | C17: 552 | D17: 351 | E17: 779 | F17: 1140 | G17: 1072 | H17: 1117 | I17: =FS!I26 -> 1423.2567 | J17: =FS!J26 -> 1581.6823 | K17: =FS!K26 -> 1644.2315 | L17: =FS!L26 -> 1685.2942 | M17: =FS!M26 -> 1788.2665
A18: Net Cash Flow from Operating Activities (A) | B18: =B8+B16-B17 -> 1508.7 | C18: =C8+C16-C17 -> 932.27 | D18: =D8+D16-D17 -> 1222 | E18: =E8+E16-E17 -> -2298 | F18: =F8+F16-F17 -> 2450 | G18: =G8+G16-G17 -> 2501 | H18: =H8+H16-H17 -> -1747 | I18: =I8+I16-I17 -> 5797.4567 | ... M18: =M8+M16-M17 -> 4646.2448
A20: B. CASH FLOW FROM INVESTING ACTIVITIES
A21: Purchase of Fixed Assets (Capex) | C21: =-Assumptions!C54 -> -397.96 | D21: =-Assumptions!D54 -> -262 | E21: =-Assumptions!E54 -> -333 | F21: =-Assumptions!F54 -> -420 | G21: =-Assumptions!G54 -> -759 | H21: =-Assumptions!H54 -> -631 | I21: =-Assumptions!I54 -> -762.50965 | J21: =-Assumptions!J54 -> -834.26907 | ... M21: =-Assumptions!M54 -> -1028.2118
A22: Net Cash Flow from Investing Activities (B) | B22: =B21 -> 0 | C22: =C21 -> -397.96 | D22: =D21 -> -262 | E22: =E21 -> -333 | F22: =F21 -> -420 | G22: =G21 -> -759 | H22: =H21 -> -631 | I22: =I21 -> -762.50965 | ... M22: =M21 -> -1028.2118
A24: C. CASH FLOW FROM FINANCING ACTIVITIES
A25: Finance Cost Paid | B25: -44.45 | C25: -149 | D25: -181 | E25: -195 | F25: -240 | G25: -480 | H25: -767 | I25: =-FS!I16 -> -543.86181 | J25: =-FS!J16 -> -587.41151 | K25: =-FS!K16 -> -657.37625 | L25: =-FS!L16 -> -753.31939 | M25: =-FS!M16 -> -810.30624
A26: Dividends Paid | C26: -873.94 | D26: -149 | E26: -360 | F26: -712 | G26: -1081 | H26: -981 | I26: =-Assumptions!I29 -> -971.47167 | J26: =-Assumptions!J29 -> -1135.7307 | K26: =-Assumptions!K29 -> -1255.3084 | L26: =-Assumptions!L29 -> -1329.9034 | M26: =-Assumptions!M29 -> -1369.0292
A27: Net Cash Flow from Financing Activities (C) | B27: =B25+B26 -> -44.45 | C27: =C25+C26 -> -1022.94 | D27: =D25+D26 -> -330 | E27: =E25+E26 -> -555 | F27: =F25+F26 -> -952 | G27: =G25+G26 -> -1561 | H27: =H25+H26 -> -1748 | I27: =I25+I26 -> -1515.3335 | ... M27: =M25+M26 -> -2179.3355
A29: Net Change in Cash (A+B+C) | B29: =B18+B22+B27 -> 1464.25 | C29: =C18+C22+C27 -> -488.63 | D29: =D18+D22+D27 -> 630 | E29: =E18+E22+E27 -> -3186 | F29: =F18+F22+F27 -> 1078 | G29: =G18+G22+G27 -> 181 | H29: =H18+H22+H27 -> -4126 | I29: =I18+I22+I27 -> 3519.6136 | ... M29: =M18+M22+M27 -> 1438.6975
A30: Add: Opening Cash Balance | C30: 1001 | D30: 356 | E30: 512 | F30: 1049 | G30: 792 | H30: 805 | I30: =FS!H72 -> 1132 | J30: =FS!I72 -> 4651.6136 | K30: =FS!J72 -> 6067.3355 | L30: =FS!K72 -> 8723.5768 | M30: =FS!L72 -> 10361.582
A31: Closing Cash Balance | C31: =C30+C29 -> 512.37 | D31: =D30+D29 -> 986 | E31: =E30+E29 -> -2674 | F31: =F30+F29 -> 2127 | G31: =G30+G29 -> 973 | H31: =H30+H29 -> -3321 | I31: =I30+I29 -> 4651.6136 | J31: =J30+J29 -> 6067.3355 | ... M31: =M30+M29 -> 11800.279
A32: CFS Check (CFS Cash - BS Cash) | I32: =I31-FS!I72 -> 9.094947e-12 | J32: =J31-FS!J72 -> 0 | K32: =K31-FS!K72 -> 0 | L32: =L31-FS!L72 -> 0 | M32: =M31-FS!M72 -> 0

Sheet OPERATING CYCLE
A1: PARTICULARS | B1: 2020 | C1: 2021 | D1: 2022 | E1: 2023 | F1: 2024 | G1: 2025
A2: COGS | B2: =Assumptions!C14 -> 14512 | C2: =Assumptions!D14 -> 15769 | D2: =Assumptions!E14 -> 20658 | E2: =Assumptions!F14 -> 29046 | F2: =Assumptions!G14 -> 36942 | G2: =Assumptions!H14 -> 43740
A3: AVERAGE INVENTORY | B3: =(FS!B70+FS!C70)/2 -> 7230.09 | C3: =(FS!C70+FS!D70)/2 -> 7862.5 | D3: =(FS!D70+FS!E70)/2 -> 10385.5 | E3: =(FS!E70+FS!F70)/2 -> 13869.5 | F3: =(FS!F70+FS!G70)/2 -> 15913 | G3: =(FS!G70+FS!H70)/2 -> 20695.5
A4: ITO | B4: =B2/B3 -> 2.0071673 | C4: =C2/C3 -> 2.0055962 | D4: =D2/D3 -> 1.9891194 | E4: =E2/E3 -> 2.0942356 | F4: =F2/F3 -> 2.3214981 | G4: =G2/G3 -> 2.1135029
A5: INVENTORY CONVERSION DAYS | B5: =252/B4 -> 125.55007 | C5: =252/C4 -> 125.64842 | D5: =252/D4 -> 126.68922 | E5: =252/E4 -> 120.3303 | F5: =252/F4 -> 108.55059 | G5: =252/G4 -> 119.23333
A7: NET SALES | B7: =FS!C8 -> 20156 | C7: =FS!D8 -> 20783 | D7: =FS!E8 -> 27456 | E7: =FS!F8 -> 38569 | F7: =FS!G8 -> 47624 | G7: =FS!H8 -> 55335
A8: AVERAGE DEBTORS | B8: =(FS!B71+FS!C71)/2 -> 286.115 | C8: =(FS!C71+FS!D71)/2 -> 252.5 | D8: =(FS!D71+FS!E71)/2 -> 393 | E8: =(FS!E71+FS!F71)/2 -> 701.5 | F8: =(FS!F71+FS!G71)/2 -> 922.5 | G8: =(FS!G71+FS!H71)/2 -> 960.5
A9: DEBTORS TURNOVER RATIO | B9: =B7/B8 -> 70.447198 | C9: =C7/C8 -> 82.308911 | D9: =D7/D8 -> 69.862595 | E9: =E7/E8 -> 54.980756 | F9: =F7/F8 -> 51.624932 | G9: =G7/G8 -> 57.610619
A10: DEBTORS CONVERSION DAYS | B10: =252/B9 -> 3.5771473 | C10: =252/C9 -> 3.0616369 | D10: =252/D9 -> 3.6070804 | E10: =252/E9 -> 4.5834219 | F10: =252/F9 -> 4.8813623 | G10: =252/G9 -> 4.3741935
A11: GROSS OPERATING CYCLE | B11: =B5+B10 -> 129.12722 | C11: =C5+C10 -> 128.71006 | D11: =D5+D10 -> 130.2963 | E11: =E5+E10 -> 124.91373 | F11: =F5+F10 -> 113.43196 | G11: =G5+G10 -> 123.60753
A13: PURCHASES | B13: =FS!C13 -> 2859 | C13: =FS!D13 -> 2462 | D13: =FS!E13 -> 4187 | E13: =FS!F13 -> 5438 | F13: =FS!G13 -> 5535 | G13: =FS!H13 -> 6372
A14: AVERAGE CREDITORS | B14: =(FS!B50+FS!C50)/2 -> 641.17 | C14: =(FS!C50+FS!D50)/2 -> 602.5 | D14: =(FS!D50+FS!E50)/2 -> 875 | E14: =(FS!E50+FS!F50)/2 -> 1010 | F14: =(FS!F50+FS!G50)/2 -> 954 | G14: =(FS!G50+FS!H50)/2 -> 1207.5
A15: CREDITOR TURNOVER RATIO | B15: =B13/B14 -> 4.4590358 | C15: =C13/C14 -> 4.0863071 | D15: =D13/D14 -> 4.7851429 | E15: =E13/E14 -> 5.3841584 | F15: =F13/F14 -> 5.8018868 | G15: =G13/G14 -> 5.2770186
A16: CREDITOR CONVERSION DAYS | B16: =252/B15 -> 56.51446 | C16: =252/C15 -> 61.669374 | D16: =252/D15 -> 52.663005 | E16: =252/E15 -> 46.803972 | F16: =252/F15 -> 43.434146 | G16: =252/G15 -> 47.754237
A17: NET OPERATING CYCLE | B17: =B11-B16 -> 72.612762 | C17: =C11-C16 -> 67.040687 | D17: =D11-D16 -> 77.6333 | E17: =E11-E16 -> 78.109754 | F17: =F11-F16 -> 69.997809 | G17: =G11-G16 -> 75.85329

Sheet DCF Valuation
A1: DISCOUNTED CASH FLOW VALUATION
A2: (INR in Cr. | WACC = 10.51% | Terminal Growth = 5%)
A3: A. FREE CASH FLOW TO FIRM (FCFF)
A4: Particulars | B4: 2026F | C4: 2027F | D4: 2028F | E4: 2029F | F4: 2030F | G4: Notes
A5: EBIT | B5: =FS!I24+FS!I16 -> 6198.8867 | C5: =FS!J24+FS!J16 -> 6871.909 | D5: =FS!K24+FS!K16 -> 7190.4005 | E5: =FS!L24+FS!L16 -> 7449.4977 | F5: =FS!M24+FS!M16 -> 7915.6244 | G5: EBIT = PBT + Finance Cost
A6: Less: Tax on EBIT | B6: =(FS!I24+FS!I16)*Assumptions!I27 -> 1560.1358 | C6: =(FS!J24+FS!J16)*Assumptions!J27 -> 1729.5221 | D6: =(FS!K24+FS!K16)*Assumptions!K27 -> 1809.68 | E6: =(FS!L24+FS!L16)*Assumptions!L27 -> 1874.8896 | F6: =(FS!M24+FS!M16)*Assumptions!M27 -> 1992.2043 | G6: EBIT * Tax Rate (25.168%)
A7: NOPAT | B7: =B5-B6 -> 4638.7509 | C7: =C5-C6 -> 5142.387 | D7: =D5-D6 -> 5380.7205 | E7: =E5-E6 -> 5574.6081 | F7: =F5-F6 -> 5923.42 | G7: EBIT * (1 – Tax Rate)
A8: Add: Depreciation & Amortisation | B8: =FS!I17 -> 543.65395 | C8: =FS!J17 -> 644.2721 | D8: =FS!K17 -> 714.28275 | E8: =FS!L17 -> 792.69204 | F8: =FS!M17 -> 858.46802 | G8: Non-cash add-back
A9: Less: Increase in Working Capital | B9: =-(FS!I77-FS!H77) -> -3041.4408 | C9: =-(FS!J77-FS!I77) -> -3377.0876 | D9: =-(FS!K77-FS!J77) -> -3443.2674 | E9: =-(FS!L77-FS!K77) -> -3465.1013 | F9: =-(FS!M77-FS!L77) -> -3778.2787 | G9: –(Closing WC – Opening WC)
A10: Less: Capital Expenditure | B10: =-Assumptions!I54 -> -762.50965 | C10: =-Assumptions!J54 -> -834.26907 | D10: =-Assumptions!K54 -> -904.49963 | E10: =-Assumptions!L54 -> -1008.5715 | F10: =-Assumptions!M54 -> -1028.2118 | G10: From PPE Schedule
A11: FREE CASH FLOW TO FIRM (FCFF) | B11: =B7+B8+B9+B10 -> 1378.4543 | C11: =C7+C8+C9+C10 -> 1575.3024 | D11: =D7+D8+D9+D10 -> 1747.2362 | E11: =E7+E8+E9+E10 -> 1893.6274 | F11: =F7+F8+F9+F10 -> 1975.3976 | G11: NOPAT + D&A + Changes in WC – Capex
A12: B. DISCOUNTING & PRESENT VALUE
A13: WACC (Discount Rate) | B13: ='WACC & EVA'!C14 -> 0.10509206 | C13: ='WACC & EVA'!C14 -> 0.10509206 | D13: ='WACC & EVA'!C14 -> 0.10509206 | E13: ='WACC & EVA'!C14 -> 0.10509206 | F13: ='WACC & EVA'!C14 -> 0.10509206 | G13: From WACC sheet
A14: Year Number (t) | B14: 1 | C14: 2 | D14: 3 | E14: 4 | F14: 5
A15: Discount Factor | B15: =1/(1+B13)^B14 -> 0.90490199 | C15: =1/(1+C13)^C14 -> 0.81884761 | D15: =1/(1+D13)^D14 -> 0.74097683 | E15: =1/(1+E13)^E14 -> 0.6705114 | F15: =1/(1+F13)^F14 -> 0.6067471 | G15: [1/(1+WACC)^t]
A16: Present Value of FCFF | B16: =B11*B15 -> 1247.3661 | C16: =C11*C15 -> 1289.9326 | D16: =D11*D15 -> 1294.6615 | E16: =E11*E15 -> 1269.6987 | F16: =F11*F15 -> 1198.5668 | G16: FCFF * Discount Factor
A17: C. TERMINAL VALUE (Gordon Growth Model)
A18: Terminal Growth Rate (g) | B18: 0.05 | C18: =B18 -> 0.05 | D18: =B18 -> 0.05 | E18: =B18 -> 0.05 | F18: =B18 -> 0.05 | G18: Change this assumption
A19: FCFF in Terminal Year (Year 5 * (1+g)) | B19: =F11*(1+B18) -> 2074.1675 | G19: FCFF2030 * (1 + g)
A20: Terminal Value | B20: =B19/(B13-B18) -> 37649.119 | G20: Next-year FCFF/(WACC – g)
A21: PV of Terminal Value | B21: =B20*F15 -> 22843.494 | G21: TV * DF5
A22: D. ENTERPRISE VALUE & EQUITY VALUE
A23: Sum of PV of FCFFs (Explicit Period) | B23: =SUM(B16:F16) -> 6300.2257 | G23: Sum of PV(FCFF) 2026–2030
A24: PV of Terminal Value | B24: =B21 -> 22843.494
A25: ENTERPRISE VALUE (EV) | B25: =B23+B24 -> 29143.72 | G25: EV = PV(FCFFs) + PV(TV)
A26: Less: Total Debt (LT + ST Borrowings + NC Lease) | B26: =FS!H43+FS!H48+FS!H44 -> 16889 | G26: LT Borrow + ST Borrow + NC Lease (FY25)
A27: Add: Cash & Cash Equivalents | B27: =FS!H72 -> 1132 | G27: FY2025 closing cash
A28: Net Debt (Total Debt – Cash) | B28: =B26-B27 -> 15757 | G28: Total Debt – Cash
A29: EQUITY VALUE | B29: =B25-B28 -> 13386.72 | G29: EV – Net Debt
A30: Shares Outstanding (Cr) | B30: =FS!H29/FS!H30 -> 88.696809 | G30: PAT/ EPS (FY25)
A31: INTRINSIC VALUE PER SHARE (DCF) | B31: =B29/B30 -> 150.92673 | G31: Equity Value/Shares
A32: E. SENSITIVITY ANALYSIS - Implied Price (Rs.) vs WACC & Terminal Growth Rate
A33: WACC \ Terminal Growth -- | B33: 0.03 | C33: 0.04 | D33: 0.05 | E33: 0.06 | F33: 0.07
A34: 0.085 | B34: 207.3 | C34: 278.7 | D34: 391 | E34: 593.2 | F34: 1064.9
A35: 0.095 | B35: 146.5 | C35: 194.2 | D35: 263.1 | E35: 371.4 | F35: 566.2
A36: 0.1051 | B36: 101.6 | C36: 135.3 | D36: 181.1 | E36: 247.3 | F36: 351.1 | G36: Base case
A37: 0.115 | B37: 68 | C37: 92.9 | D37: 125.4 | E37: 169.8 | F37: 233.9
A38: 0.125 | B38: 41.2 | C38: 60.1 | D38: 84.2 | E38: 115.5 | F38: 158.4
A39: Note: Sensitivity uses pre-computed FCFF values. Green = above Rs.150, Red = below Rs.150, Yellow = base case row.

Sheet Relative Valuation
A1: RELATIVE VALUATION
A2: (INR in Cr. | Peer multiples applied to Titan FY2026 forecasts)
A3: A. TITAN - KEY FINANCIAL METRICS
A4: Particulars | B4: FY2021A | C4: FY2022A | D4: FY2023A | E4: FY2024A | F4: FY2025A | G4: FY2026F | H4: FY2027F | I4: FY2028F
A5: Revenue (Cr) | B5: =FS!D8 -> 20783 | C5: =FS!E8 -> 27456 | D5: =FS!F8 -> 38569 | E5: =FS!G8 -> 47624 | F5: =FS!H8 -> 55335 | G5: =FS!I8 -> 59129.682 | H5: =FS!J8 -> 63206.629 | I5: =FS!K8 -> 67549.826
